<?xml version="0.0" ?>
<robot name="">
	<link name="base_footprint">
		<inertial>
			<origin rpy="0.00000 -0.00000 0.00000" xyz="0.00000 0.00000 0.00000"/>
			<mass value="1.00000"/>
			<inertia ixx="0.00000" ixy="0" ixz="0" iyy="0.00000" iyz="0" izz="0.00000"/>
		</inertial>
	</link>
	<link name="base_link">
		<inertial>
			<origin rpy="0.00000 -0.00000 0.00000" xyz="-0.08748 -0.00085 0.09947"/>
			<mass value="33.45500"/>
			<inertia ixx="1.11752" ixy="0" ixz="0" iyy="3.04306" iyz="0" izz="3.75561"/>
		</inertial>
		<visual>
			<origin rpy="0.00000 -0.00000 0.00000" xyz="0.00000 0.00000 0.00000"/>
			<geometry>
				<mesh filename="/home/guillaume/Documents/Research/DRL/venv/lib/python3.6/site-packages/pybullet_data/husky/meshes/base_link.stl" scale="1.00000 1.00000 1.00000"/>
			</geometry>
			<material name="mat_0_0">
				<color rgba="0.10000 0.10000 0.10000 1.00000" />
			</material>
		</visual>
		<collision>
			<origin rpy="0.00000 -0.00000 0.00000" xyz="0.00000 0.00000 0.12498"/>
			<geometry>
				<box size="1.00740 0.57090 0.26750"/>
			</geometry>
		</collision>
	</link>
	<link name="imu_link">
		<inertial>
			<origin rpy="0.00000 -0.00000 0.00000" xyz="0.00000 0.00000 0.00000"/>
			<mass value="1.00000"/>
			<inertia ixx="0.00000" ixy="0" ixz="0" iyy="0.00000" iyz="0" izz="0.00000"/>
		</inertial>
	</link>
	<link name="front_left_wheel_link">
		<inertial>
			<origin rpy="0.00000 -0.00000 0.00000" xyz="0.00000 0.00000 0.00000"/>
			<mass value="2.63700"/>
			<inertia ixx="0.03106" ixy="0" ixz="0" iyy="0.05617" iyz="0" izz="0.03106"/>
		</inertial>
		<visual>
			<origin rpy="0.00000 -0.00000 0.00000" xyz="0.00000 0.00000 0.00000"/>
			<geometry>
				<mesh filename="/home/guillaume/Documents/Research/DRL/venv/lib/python3.6/site-packages/pybullet_data/husky/meshes/wheel.stl" scale="1.00000 1.00000 1.00000"/>
			</geometry>
			<material name="mat_2_0">
				<color rgba="0.30000 0.30000 0.30000 1.00000" />
			</material>
		</visual>
		<collision>
			<origin rpy="1.57079 -0.00000 0.00000" xyz="0.00000 0.00000 0.00000"/>
			<geometry>
				<cylinder length="0.11430" radius="0.17775"/>
			</geometry>
		</collision>
	</link>
	<link name="front_right_wheel_link">
		<inertial>
			<origin rpy="0.00000 -0.00000 0.00000" xyz="0.00000 0.00000 0.00000"/>
			<mass value="2.63700"/>
			<inertia ixx="0.03106" ixy="0" ixz="0" iyy="0.05617" iyz="0" izz="0.03106"/>
		</inertial>
		<visual>
			<origin rpy="0.00000 -0.00000 0.00000" xyz="0.00000 0.00000 0.00000"/>
			<geometry>
				<mesh filename="/home/guillaume/Documents/Research/DRL/venv/lib/python3.6/site-packages/pybullet_data/husky/meshes/wheel.stl" scale="1.00000 1.00000 1.00000"/>
			</geometry>
			<material name="mat_3_0">
				<color rgba="0.30000 0.30000 0.30000 1.00000" />
			</material>
		</visual>
		<collision>
			<origin rpy="1.57079 -0.00000 0.00000" xyz="0.00000 0.00000 0.00000"/>
			<geometry>
				<cylinder length="0.11430" radius="0.17775"/>
			</geometry>
		</collision>
	</link>
	<link name="rear_left_wheel_link">
		<inertial>
			<origin rpy="0.00000 -0.00000 0.00000" xyz="0.00000 0.00000 0.00000"/>
			<mass value="2.63700"/>
			<inertia ixx="0.03106" ixy="0" ixz="0" iyy="0.05617" iyz="0" izz="0.03106"/>
		</inertial>
		<visual>
			<origin rpy="0.00000 -0.00000 0.00000" xyz="0.00000 0.00000 0.00000"/>
			<geometry>
				<mesh filename="/home/guillaume/Documents/Research/DRL/venv/lib/python3.6/site-packages/pybullet_data/husky/meshes/wheel.stl" scale="1.00000 1.00000 1.00000"/>
			</geometry>
			<material name="mat_4_0">
				<color rgba="0.30000 0.30000 0.30000 1.00000" />
			</material>
		</visual>
		<collision>
			<origin rpy="1.57079 -0.00000 0.00000" xyz="0.00000 0.00000 0.00000"/>
			<geometry>
				<cylinder length="0.11430" radius="0.17775"/>
			</geometry>
		</collision>
	</link>
	<link name="rear_right_wheel_link">
		<inertial>
			<origin rpy="0.00000 -0.00000 0.00000" xyz="0.00000 0.00000 0.00000"/>
			<mass value="2.63700"/>
			<inertia ixx="0.03106" ixy="0" ixz="0" iyy="0.05617" iyz="0" izz="0.03106"/>
		</inertial>
		<visual>
			<origin rpy="0.00000 -0.00000 0.00000" xyz="0.00000 0.00000 0.00000"/>
			<geometry>
				<mesh filename="/home/guillaume/Documents/Research/DRL/venv/lib/python3.6/site-packages/pybullet_data/husky/meshes/wheel.stl" scale="1.00000 1.00000 1.00000"/>
			</geometry>
			<material name="mat_5_0">
				<color rgba="0.30000 0.30000 0.30000 1.00000" />
			</material>
		</visual>
		<collision>
			<origin rpy="1.57079 -0.00000 0.00000" xyz="0.00000 0.00000 0.00000"/>
			<geometry>
				<cylinder length="0.11430" radius="0.17775"/>
			</geometry>
		</collision>
	</link>
	<link name="top_plate_link">
		<inertial>
			<origin rpy="0.00000 -0.00000 0.00000" xyz="0.00000 0.00000 0.00000"/>
			<mass value="1.00000"/>
			<inertia ixx="0.00000" ixy="0" ixz="0" iyy="0.00000" iyz="0" izz="0.00000"/>
		</inertial>
		<visual>
			<origin rpy="0.00000 -0.00000 0.00000" xyz="0.00000 0.00000 0.00000"/>
			<geometry>
				<mesh filename="/home/guillaume/Documents/Research/DRL/venv/lib/python3.6/site-packages/pybullet_data/husky/meshes/top_plate.stl" scale="1.00000 1.00000 1.00000"/>
			</geometry>
			<material name="mat_6_0">
				<color rgba="0.80000 0.80000 0.00000 1.00000" />
			</material>
		</visual>
	</link>
	<link name="user_rail_link">
		<inertial>
			<origin rpy="0.00000 -0.00000 0.00000" xyz="0.00000 0.00000 0.00000"/>
			<mass value="1.00000"/>
			<inertia ixx="0.00000" ixy="0" ixz="0" iyy="0.00000" iyz="0" izz="0.00000"/>
		</inertial>
		<visual>
			<origin rpy="0.00000 -0.00000 0.00000" xyz="0.00000 0.00000 0.00000"/>
			<geometry>
				<mesh filename="/home/guillaume/Documents/Research/DRL/venv/lib/python3.6/site-packages/pybullet_data/husky/meshes/user_rail.stl" scale="1.00000 1.00000 1.00000"/>
			</geometry>
			<material name="mat_7_0">
				<color rgba="0.30000 0.30000 0.30000 1.00000" />
			</material>
		</visual>
	</link>
	<link name="front_bumper_link">
		<inertial>
			<origin rpy="0.00000 -0.00000 0.00000" xyz="0.00000 0.00000 0.00000"/>
			<mass value="1.00000"/>
			<inertia ixx="0.00000" ixy="0" ixz="0" iyy="0.00000" iyz="0" izz="0.00000"/>
		</inertial>
		<visual>
			<origin rpy="0.00000 -0.00000 0.00000" xyz="0.00000 0.00000 0.00000"/>
			<geometry>
				<mesh filename="/home/guillaume/Documents/Research/DRL/venv/lib/python3.6/site-packages/pybullet_data/husky/meshes/bumper.stl" scale="1.00000 1.00000 1.00000"/>
			</geometry>
			<material name="mat_8_0">
				<color rgba="0.30000 0.30000 0.30000 1.00000" />
			</material>
		</visual>
	</link>
	<link name="rear_bumper_link">
		<inertial>
			<origin rpy="0.00000 -0.00000 0.00000" xyz="0.00000 0.00000 0.00000"/>
			<mass value="1.00000"/>
			<inertia ixx="0.00000" ixy="0" ixz="0" iyy="0.00000" iyz="0" izz="0.00000"/>
		</inertial>
		<visual>
			<origin rpy="0.00000 -0.00000 0.00000" xyz="0.00000 0.00000 0.00000"/>
			<geometry>
				<mesh filename="/home/guillaume/Documents/Research/DRL/venv/lib/python3.6/site-packages/pybullet_data/husky/meshes/bumper.stl" scale="1.00000 1.00000 1.00000"/>
			</geometry>
			<material name="mat_9_0">
				<color rgba="0.30000 0.30000 0.30000 1.00000" />
			</material>
		</visual>
	</link>
	<link name="lbr_iiwa_link_0">
		<inertial>
			<origin rpy="0.00000 -0.00000 0.00000" xyz="-0.10000 0.00000 0.07000"/>
			<mass value="0.00000"/>
			<inertia ixx="0.00000" ixy="0" ixz="0" iyy="0.00000" iyz="0" izz="0.00000"/>
		</inertial>
		<visual>
			<origin rpy="0.00000 -0.00000 0.00000" xyz="0.00000 0.00000 0.00000"/>
			<geometry>
				<mesh filename="/home/guillaume/Documents/Research/DRL/venv/lib/python3.6/site-packages/pybullet_data/kuka_iiwa/meshes/link_0.obj" scale="1.00000 1.00000 1.00000"/>
			</geometry>
			<material name="mat_-1_0">
				<color rgba="0.20000 0.20000 0.20000 1.00000" />
			</material>
		</visual>
		<collision>
			<origin rpy="0.00000 -0.00000 0.00000" xyz="0.00000 0.00000 0.00000"/>
			<geometry>
				<mesh filename="/home/guillaume/Documents/Research/DRL/venv/lib/python3.6/site-packages/pybullet_data/kuka_iiwa/meshes/link_0.stl" scale="1.00000 1.00000 1.00000"/>
			</geometry>
		</collision>
	</link>
	<link name="lbr_iiwa_link_1">
		<inertial>
			<origin rpy="0.00000 -0.00000 0.00000" xyz="0.00000 -0.03000 0.12000"/>
			<mass value="4.00000"/>
			<inertia ixx="0.04509" ixy="0" ixz="0" iyy="0.04124" iyz="0" izz="0.02474"/>
		</inertial>
		<visual>
			<origin rpy="0.00000 -0.00000 0.00000" xyz="0.00000 0.00000 0.00000"/>
			<geometry>
				<mesh filename="/home/guillaume/Documents/Research/DRL/venv/lib/python3.6/site-packages/pybullet_data/kuka_iiwa/meshes/link_1.obj" scale="1.00000 1.00000 1.00000"/>
			</geometry>
			<material name="mat_0_0">
				<color rgba="0.50000 0.70000 1.00000 1.00000" />
			</material>
		</visual>
		<collision>
			<origin rpy="0.00000 -0.00000 0.00000" xyz="0.00000 0.00000 0.00000"/>
			<geometry>
				<mesh filename="/home/guillaume/Documents/Research/DRL/venv/lib/python3.6/site-packages/pybullet_data/kuka_iiwa/meshes/link_1.stl" scale="1.00000 1.00000 1.00000"/>
			</geometry>
		</collision>
	</link>
	<link name="lbr_iiwa_link_2">
		<inertial>
			<origin rpy="0.00000 -0.00000 0.00000" xyz="0.00030 0.05900 0.04200"/>
			<mass value="4.00000"/>
			<inertia ixx="0.04343" ixy="0" ixz="0" iyy="0.02460" iyz="0" izz="0.03965"/>
		</inertial>
		<visual>
			<origin rpy="0.00000 -0.00000 0.00000" xyz="0.00000 0.00000 0.00000"/>
			<geometry>
				<mesh filename="/home/guillaume/Documents/Research/DRL/venv/lib/python3.6/site-packages/pybullet_data/kuka_iiwa/meshes/link_2.obj" scale="1.00000 1.00000 1.00000"/>
			</geometry>
			<material name="mat_1_0">
				<color rgba="0.50000 0.70000 1.00000 1.00000" />
			</material>
		</visual>
		<collision>
			<origin rpy="0.00000 -0.00000 0.00000" xyz="0.00000 0.00000 0.00000"/>
			<geometry>
				<mesh filename="/home/guillaume/Documents/Research/DRL/venv/lib/python3.6/site-packages/pybullet_data/kuka_iiwa/meshes/link_2.stl" scale="1.00000 1.00000 1.00000"/>
			</geometry>
		</collision>
	</link>
	<link name="lbr_iiwa_link_3">
		<inertial>
			<origin rpy="0.00000 -0.00000 0.00000" xyz="0.00000 0.03000 0.13000"/>
			<mass value="3.00000"/>
			<inertia ixx="0.03130" ixy="0" ixz="0" iyy="0.02744" iyz="0" izz="0.01394"/>
		</inertial>
		<visual>
			<origin rpy="0.00000 -0.00000 0.00000" xyz="0.00000 0.00000 0.00000"/>
			<geometry>
				<mesh filename="/home/guillaume/Documents/Research/DRL/venv/lib/python3.6/site-packages/pybullet_data/kuka_iiwa/meshes/link_3.obj" scale="1.00000 1.00000 1.00000"/>
			</geometry>
			<material name="mat_2_0">
				<color rgba="1.00000 0.42353 0.03922 1.00000" />
			</material>
		</visual>
		<collision>
			<origin rpy="0.00000 -0.00000 0.00000" xyz="0.00000 0.00000 0.00000"/>
			<geometry>
				<mesh filename="/home/guillaume/Documents/Research/DRL/venv/lib/python3.6/site-packages/pybullet_data/kuka_iiwa/meshes/link_3.stl" scale="1.00000 1.00000 1.00000"/>
			</geometry>
		</collision>
	</link>
	<link name="lbr_iiwa_link_4">
		<inertial>
			<origin rpy="0.00000 -0.00000 0.00000" xyz="0.00000 0.06700 0.03400"/>
			<mass value="2.70000"/>
			<inertia ixx="0.02302" ixy="0" ixz="0" iyy="0.01255" iyz="0" izz="0.01957"/>
		</inertial>
		<visual>
			<origin rpy="0.00000 -0.00000 0.00000" xyz="0.00000 0.00000 0.00000"/>
			<geometry>
				<mesh filename="/home/guillaume/Documents/Research/DRL/venv/lib/python3.6/site-packages/pybullet_data/kuka_iiwa/meshes/link_4.obj" scale="1.00000 1.00000 1.00000"/>
			</geometry>
			<material name="mat_3_0">
				<color rgba="0.50000 0.70000 1.00000 1.00000" />
			</material>
		</visual>
		<collision>
			<origin rpy="0.00000 -0.00000 0.00000" xyz="0.00000 0.00000 0.00000"/>
			<geometry>
				<mesh filename="/home/guillaume/Documents/Research/DRL/venv/lib/python3.6/site-packages/pybullet_data/kuka_iiwa/meshes/link_4.stl" scale="1.00000 1.00000 1.00000"/>
			</geometry>
		</collision>
	</link>
	<link name="lbr_iiwa_link_5">
		<inertial>
			<origin rpy="0.00000 -0.00000 0.00000" xyz="0.00010 0.02100 0.07600"/>
			<mass value="1.70000"/>
			<inertia ixx="0.01559" ixy="0" ixz="0" iyy="0.01421" iyz="0" izz="0.00710"/>
		</inertial>
		<visual>
			<origin rpy="0.00000 -0.00000 0.00000" xyz="0.00000 0.00000 0.00000"/>
			<geometry>
				<mesh filename="/home/guillaume/Documents/Research/DRL/venv/lib/python3.6/site-packages/pybullet_data/kuka_iiwa/meshes/link_5.obj" scale="1.00000 1.00000 1.00000"/>
			</geometry>
			<material name="mat_4_0">
				<color rgba="0.50000 0.70000 1.00000 1.00000" />
			</material>
		</visual>
		<collision>
			<origin rpy="0.00000 -0.00000 0.00000" xyz="0.00000 0.00000 0.00000"/>
			<geometry>
				<mesh filename="/home/guillaume/Documents/Research/DRL/venv/lib/python3.6/site-packages/pybullet_data/kuka_iiwa/meshes/link_5.stl" scale="1.00000 1.00000 1.00000"/>
			</geometry>
		</collision>
	</link>
	<link name="lbr_iiwa_link_6">
		<inertial>
			<origin rpy="0.00000 -0.00000 0.00000" xyz="0.00000 0.00060 0.00040"/>
			<mass value="1.80000"/>
			<inertia ixx="0.00761" ixy="0" ixz="0" iyy="0.00597" iyz="0" izz="0.00738"/>
		</inertial>
		<visual>
			<origin rpy="0.00000 -0.00000 0.00000" xyz="0.00000 0.00000 0.00000"/>
			<geometry>
				<mesh filename="/home/guillaume/Documents/Research/DRL/venv/lib/python3.6/site-packages/pybullet_data/kuka_iiwa/meshes/link_6.obj" scale="1.00000 1.00000 1.00000"/>
			</geometry>
			<material name="mat_5_0">
				<color rgba="1.00000 0.42353 0.03922 1.00000" />
			</material>
		</visual>
		<collision>
			<origin rpy="0.00000 -0.00000 0.00000" xyz="0.00000 0.00000 0.00000"/>
			<geometry>
				<mesh filename="/home/guillaume/Documents/Research/DRL/venv/lib/python3.6/site-packages/pybullet_data/kuka_iiwa/meshes/link_6.stl" scale="1.00000 1.00000 1.00000"/>
			</geometry>
		</collision>
	</link>
	<link name="lbr_iiwa_link_7">
		<inertial>
			<origin rpy="0.00000 -0.00000 0.00000" xyz="0.00000 0.00000 0.02000"/>
			<mass value="0.30000"/>
			<inertia ixx="0.00039" ixy="0" ixz="0" iyy="0.00040" iyz="0" izz="0.00060"/>
		</inertial>
		<visual>
			<origin rpy="0.00000 -0.00000 0.00000" xyz="0.00000 0.00000 0.00000"/>
			<geometry>
				<mesh filename="/home/guillaume/Documents/Research/DRL/venv/lib/python3.6/site-packages/pybullet_data/kuka_iiwa/meshes/link_7.obj" scale="1.00000 1.00000 1.00000"/>
			</geometry>
			<material name="mat_6_0">
				<color rgba="0.20000 0.20000 0.20000 1.00000" />
			</material>
		</visual>
		<collision>
			<origin rpy="0.00000 -0.00000 0.00000" xyz="0.00000 0.00000 0.00000"/>
			<geometry>
				<mesh filename="/home/guillaume/Documents/Research/DRL/venv/lib/python3.6/site-packages/pybullet_data/kuka_iiwa/meshes/link_7.stl" scale="1.00000 1.00000 1.00000"/>
			</geometry>
		</collision>
	</link>
	<joint name="chassis_joint" type="fixed">
		<parent link="base_footprint"/>
		<child link="base_link"/>
		<dynamics damping="1.0" friction="0.0001"/>
		<origin rpy="0.00000 -0.00000 0.00000" xyz="0.00000 0.00000 0.14493"/>
		<axis xyz="0.00000 0.00000 0.00000"/>
	</joint>
	<joint name="imu_joint" type="fixed">
		<parent link="base_link"/>
		<child link="imu_link"/>
		<dynamics damping="1.0" friction="0.0001"/>
		<origin rpy="0.00000 -0.00000 0.00000" xyz="0.00000 0.00000 0.19000"/>
		<axis xyz="0.00000 0.00000 0.00000"/>
	</joint>
	<joint name="front_left_wheel" type="continuous">
		<parent link="base_link"/>
		<child link="front_left_wheel_link"/>
		<dynamics damping="1.0" friction="0.0001"/>
		<origin rpy="0.00000 -0.00000 0.00000" xyz="0.25600 0.28540 0.03282"/>
		<axis xyz="0.00000 1.00000 0.00000"/>
	</joint>
	<joint name="front_right_wheel" type="continuous">
		<parent link="base_link"/>
		<child link="front_right_wheel_link"/>
		<dynamics damping="1.0" friction="0.0001"/>
		<origin rpy="0.00000 -0.00000 0.00000" xyz="0.25600 -0.28540 0.03282"/>
		<axis xyz="0.00000 1.00000 0.00000"/>
	</joint>
	<joint name="rear_left_wheel" type="continuous">
		<parent link="base_link"/>
		<child link="rear_left_wheel_link"/>
		<dynamics damping="1.0" friction="0.0001"/>
		<origin rpy="0.00000 -0.00000 0.00000" xyz="-0.25600 0.28540 0.03282"/>
		<axis xyz="0.00000 1.00000 0.00000"/>
	</joint>
	<joint name="rear_right_wheel" type="continuous">
		<parent link="base_link"/>
		<child link="rear_right_wheel_link"/>
		<dynamics damping="1.0" friction="0.0001"/>
		<origin rpy="0.00000 -0.00000 0.00000" xyz="-0.25600 -0.28540 0.03282"/>
		<axis xyz="0.00000 1.00000 0.00000"/>
	</joint>
	<joint name="top_plate" type="fixed">
		<parent link="base_link"/>
		<child link="top_plate_link"/>
		<dynamics damping="1.0" friction="0.0001"/>
		<origin rpy="0.00000 -0.00000 0.00000" xyz="0.00000 0.00000 0.00000"/>
		<axis xyz="0.00000 0.00000 0.00000"/>
	</joint>
	<joint name="user_rail" type="fixed">
		<parent link="base_link"/>
		<child link="user_rail_link"/>
		<dynamics damping="1.0" friction="0.0001"/>
		<origin rpy="0.00000 -0.00000 0.00000" xyz="0.27200 0.00000 0.24500"/>
		<axis xyz="0.00000 0.00000 0.00000"/>
	</joint>
	<joint name="front_bumper" type="fixed">
		<parent link="base_link"/>
		<child link="front_bumper_link"/>
		<dynamics damping="1.0" friction="0.0001"/>
		<origin rpy="0.00000 -0.00000 0.00000" xyz="0.48000 0.00000 0.09100"/>
		<axis xyz="0.00000 0.00000 0.00000"/>
	</joint>
	<joint name="rear_bumper" type="fixed">
		<parent link="base_link"/>
		<child link="rear_bumper_link"/>
		<dynamics damping="1.0" friction="0.0001"/>
		<origin rpy="0.00000 -0.00000 3.14159" xyz="-0.48000 0.00000 0.09100"/>
		<axis xyz="0.00000 0.00000 0.00000"/>
	</joint>
	<joint name="joint_dummy1" type="fixed">
		<parent link="base_footprint"/>
		<child link="lbr_iiwa_link_0"/>
		<dynamics damping="1.0" friction="0.0001"/>
		<origin rpy="0.00000 0.00000 0.00000" xyz="0.00000 0.00000 0.00000"/>
		<axis xyz="0.00000 0.00000 1.00000"/>
	</joint>
	<joint name="lbr_iiwa_joint_1" type="revolute">
		<parent link="lbr_iiwa_link_0"/>
		<child link="lbr_iiwa_link_1"/>
		<dynamics damping="1.0" friction="0.0001"/>
		<origin rpy="0.00000 -0.00000 0.00000" xyz="0.00000 0.00000 0.15750"/>
		<axis xyz="0.00000 0.00000 1.00000"/>
	</joint>
	<joint name="lbr_iiwa_joint_2" type="revolute">
		<parent link="lbr_iiwa_link_1"/>
		<child link="lbr_iiwa_link_2"/>
		<dynamics damping="1.0" friction="0.0001"/>
		<origin rpy="1.57080 -0.00000 -3.14159" xyz="0.00000 0.00000 0.20250"/>
		<axis xyz="0.00000 0.00000 1.00000"/>
	</joint>
	<joint name="lbr_iiwa_joint_3" type="revolute">
		<parent link="lbr_iiwa_link_2"/>
		<child link="lbr_iiwa_link_3"/>
		<dynamics damping="1.0" friction="0.0001"/>
		<origin rpy="1.57080 -0.00000 -3.14159" xyz="0.00000 0.20450 0.00000"/>
		<axis xyz="0.00000 0.00000 1.00000"/>
	</joint>
	<joint name="lbr_iiwa_joint_4" type="revolute">
		<parent link="lbr_iiwa_link_3"/>
		<child link="lbr_iiwa_link_4"/>
		<dynamics damping="1.0" friction="0.0001"/>
		<origin rpy="1.57080 -0.00000 0.00000" xyz="0.00000 0.00000 0.21550"/>
		<axis xyz="0.00000 0.00000 1.00000"/>
	</joint>
	<joint name="lbr_iiwa_joint_5" type="revolute">
		<parent link="lbr_iiwa_link_4"/>
		<child link="lbr_iiwa_link_5"/>
		<dynamics damping="1.0" friction="0.0001"/>
		<origin rpy="1.57080 -0.00000 3.14159" xyz="0.00000 0.18450 0.00000"/>
		<axis xyz="0.00000 0.00000 1.00000"/>
	</joint>
	<joint name="lbr_iiwa_joint_6" type="revolute">
		<parent link="lbr_iiwa_link_5"/>
		<child link="lbr_iiwa_link_6"/>
		<dynamics damping="1.0" friction="0.0001"/>
		<origin rpy="1.57080 -0.00000 0.00000" xyz="0.00000 0.00000 0.21550"/>
		<axis xyz="0.00000 0.00000 1.00000"/>
	</joint>
	<joint name="lbr_iiwa_joint_7" type="revolute">
		<parent link="lbr_iiwa_link_6"/>
		<child link="lbr_iiwa_link_7"/>
		<dynamics damping="1.0" friction="0.0001"/>
		<origin rpy="1.57080 -0.00000 3.14159" xyz="0.00000 0.08100 0.00000"/>
		<axis xyz="0.00000 0.00000 1.00000"/>
	</joint>
</robot>
